<?xml version="1.0"?>
<robot name="diff_drive_bot">
  <link name="base_link">
    <visual>
      <geometry>
        <box size="0.35 0.28 0.12"/>
      </geometry>
      <material name="blue">
        <color rgba="0.2 0.3 0.8 1.0"/>
      </material>
    </visual>
    <collision>
      <geometry>
        <box size="0.35 0.28 0.12"/>
      </geometry>
    </collision>
    <inertial>
      <mass value="3.0"/>
      <origin xyz="0 0 0"/>
      <inertia ixx="0.03" ixy="0" ixz="0" iyy="0.03" iyz="0" izz="0.03"/>
    </inertial>
  </link>

  <gazebo reference="base_link">
    <plugin name="diff_drive_controller" filename="libgazebo_ros_diff_drive.so">
      <ros>
        <namespace>/</namespace>
      </ros>
      <command_topic>cmd_vel</command_topic>
      <odometry_topic>odom</odometry_topic>
      <odometry_frame>odom</odometry_frame>
      <robot_base_frame>base_link</robot_base_frame>
      <left_joint>left_wheel_joint</left_joint>
      <right_joint>right_wheel_joint</right_joint>
      <wheel_separation>0.24</wheel_separation>
      <wheel_diameter>0.12</wheel_diameter>
      <publish_odom>true</publish_odom>
    </plugin>
  </gazebo>

  <gazebo reference="base_link">
    <sensor name="front_laser" type="ray">
      <pose>0.12 0 0.08 0 0 0</pose>
      <update_rate>15</update_rate>
      <ray>
        <scan>
          <horizontal>
            <samples>180</samples>
            <resolution>1</resolution>
            <min_angle>-1.57</min_angle>
            <max_angle>1.57</max_angle>
          </horizontal>
        </scan>
        <range>
          <min>0.12</min>
          <max>8.0</max>
          <resolution>0.01</resolution>
        </range>
      </ray>
      <plugin name="laser_plugin" filename="libgazebo_ros_ray_sensor.so">
        <ros>
          <remapping>~/out:=scan</remapping>
        </ros>
        <output_type>sensor_msgs/LaserScan</output_type>
        <frame_name>base_link</frame_name>
      </plugin>
    </sensor>
  </gazebo>

  <link name="left_wheel"/>
  <link name="right_wheel"/>

  <joint name="left_wheel_joint" type="continuous">
    <parent link="base_link"/>
    <child link="left_wheel"/>
    <origin xyz="0 0.12 -0.04" rpy="0 1.5708 0"/>
    <axis xyz="0 0 1"/>
  </joint>

  <joint name="right_wheel_joint" type="continuous">
    <parent link="base_link"/>
    <child link="right_wheel"/>
    <origin xyz="0 -0.12 -0.04" rpy="0 1.5708 0"/>
    <axis xyz="0 0 1"/>
  </joint>
</robot>
